Traceback (most recent call last):
  File "/opt/miniconda3/lib/python3.9/site-packages/jupyter_cache/executors/utils.py", line 58, in single_nb_execution
    executenb(
  File "/opt/miniconda3/lib/python3.9/site-packages/nbclient/client.py", line 1204, in execute
    return NotebookClient(nb=nb, resources=resources, km=km, **kwargs).execute()
  File "/opt/miniconda3/lib/python3.9/site-packages/nbclient/util.py", line 84, in wrapped
    return just_run(coro(*args, **kwargs))
  File "/opt/miniconda3/lib/python3.9/site-packages/nbclient/util.py", line 62, in just_run
    return loop.run_until_complete(coro)
  File "/opt/miniconda3/lib/python3.9/asyncio/base_events.py", line 647, in run_until_complete
    return future.result()
  File "/opt/miniconda3/lib/python3.9/site-packages/nbclient/client.py", line 663, in async_execute
    await self.async_execute_cell(
  File "/opt/miniconda3/lib/python3.9/site-packages/nbclient/client.py", line 965, in async_execute_cell
    await self._check_raise_for_error(cell, cell_index, exec_reply)
  File "/opt/miniconda3/lib/python3.9/site-packages/nbclient/client.py", line 862, in _check_raise_for_error
    raise CellExecutionError.from_cell_and_msg(cell, exec_reply_content)
nbclient.exceptions.CellExecutionError: An error occurred while executing the following cell:
------------------
file_clase = "07_modulos_biblioteca_bis.ipynb"
shutil.copy(file_found,file_clase)
------------------

[0;31m---------------------------------------------------------------------------[0m
[0;31mSameFileError[0m                             Traceback (most recent call last)
Cell [0;32mIn[18], line 2[0m
[1;32m      1[0m file_clase [38;5;241m=[39m [38;5;124m"[39m[38;5;124m07_modulos_biblioteca_bis.ipynb[39m[38;5;124m"[39m
[0;32m----> 2[0m [43mshutil[49m[38;5;241;43m.[39;49m[43mcopy[49m[43m([49m[43mfile_found[49m[43m,[49m[43mfile_clase[49m[43m)[49m

File [0;32m/opt/miniconda3/lib/python3.9/shutil.py:427[0m, in [0;36mcopy[0;34m(src, dst, follow_symlinks)[0m
[1;32m    425[0m [38;5;28;01mif[39;00m os[38;5;241m.[39mpath[38;5;241m.[39misdir(dst):
[1;32m    426[0m     dst [38;5;241m=[39m os[38;5;241m.[39mpath[38;5;241m.[39mjoin(dst, os[38;5;241m.[39mpath[38;5;241m.[39mbasename(src))
[0;32m--> 427[0m [43mcopyfile[49m[43m([49m[43msrc[49m[43m,[49m[43m [49m[43mdst[49m[43m,[49m[43m [49m[43mfollow_symlinks[49m[38;5;241;43m=[39;49m[43mfollow_symlinks[49m[43m)[49m
[1;32m    428[0m copymode(src, dst, follow_symlinks[38;5;241m=[39mfollow_symlinks)
[1;32m    429[0m [38;5;28;01mreturn[39;00m dst

File [0;32m/opt/miniconda3/lib/python3.9/shutil.py:244[0m, in [0;36mcopyfile[0;34m(src, dst, follow_symlinks)[0m
[1;32m    241[0m sys[38;5;241m.[39maudit([38;5;124m"[39m[38;5;124mshutil.copyfile[39m[38;5;124m"[39m, src, dst)
[1;32m    243[0m [38;5;28;01mif[39;00m _samefile(src, dst):
[0;32m--> 244[0m     [38;5;28;01mraise[39;00m SameFileError([38;5;124m"[39m[38;5;132;01m{!r}[39;00m[38;5;124m and [39m[38;5;132;01m{!r}[39;00m[38;5;124m are the same file[39m[38;5;124m"[39m[38;5;241m.[39mformat(src, dst))
[1;32m    246[0m file_size [38;5;241m=[39m [38;5;241m0[39m
[1;32m    247[0m [38;5;28;01mfor[39;00m i, fn [38;5;129;01min[39;00m [38;5;28menumerate[39m([src, dst]):

[0;31mSameFileError[0m: './07_modulos_biblioteca_bis.ipynb' and '07_modulos_biblioteca_bis.ipynb' are the same file
SameFileError: './07_modulos_biblioteca_bis.ipynb' and '07_modulos_biblioteca_bis.ipynb' are the same file

