Traceback (most recent call last):
  File "/opt/miniconda3/lib/python3.9/site-packages/jupyter_cache/executors/utils.py", line 58, in single_nb_execution
    executenb(
  File "/opt/miniconda3/lib/python3.9/site-packages/nbclient/client.py", line 1204, in execute
    return NotebookClient(nb=nb, resources=resources, km=km, **kwargs).execute()
  File "/opt/miniconda3/lib/python3.9/site-packages/nbclient/util.py", line 84, in wrapped
    return just_run(coro(*args, **kwargs))
  File "/opt/miniconda3/lib/python3.9/site-packages/nbclient/util.py", line 62, in just_run
    return loop.run_until_complete(coro)
  File "/opt/miniconda3/lib/python3.9/asyncio/base_events.py", line 647, in run_until_complete
    return future.result()
  File "/opt/miniconda3/lib/python3.9/site-packages/nbclient/client.py", line 663, in async_execute
    await self.async_execute_cell(
  File "/opt/miniconda3/lib/python3.9/site-packages/nbclient/client.py", line 965, in async_execute_cell
    await self._check_raise_for_error(cell, cell_index, exec_reply)
  File "/opt/miniconda3/lib/python3.9/site-packages/nbclient/client.py", line 862, in _check_raise_for_error
    raise CellExecutionError.from_cell_and_msg(cell, exec_reply_content)
nbclient.exceptions.CellExecutionError: An error occurred while executing the following cell:
------------------
range('a','z')
------------------

[0;31m---------------------------------------------------------------------------[0m
[0;31mTypeError[0m                                 Traceback (most recent call last)
Cell [0;32mIn[6], line 1[0m
[0;32m----> 1[0m [38;5;28;43mrange[39;49m[43m([49m[38;5;124;43m'[39;49m[38;5;124;43ma[39;49m[38;5;124;43m'[39;49m[43m,[49m[38;5;124;43m'[39;49m[38;5;124;43mz[39;49m[38;5;124;43m'[39;49m[43m)[49m

[0;31mTypeError[0m: 'str' object cannot be interpreted as an integer
TypeError: 'str' object cannot be interpreted as an integer

